#VRML_SIM R2025a utf8

EXTERNPROTO "https://raw.githubusercontent.com/cyberbotics/webots/R2022b/projects/objects/backgrounds/protos/TexturedBackground.proto"
EXTERNPROTO "https://raw.githubusercontent.com/cyberbotics/webots/R2022b/projects/objects/backgrounds/protos/TexturedBackgroundLight.proto"
EXTERNPROTO "https://raw.githubusercontent.com/cyberbotics/webots/R2022b/projects/objects/floors/protos/CircleArena.proto"
EXTERNPROTO "https://raw.githubusercontent.com/cyberbotics/webots/R2025a/projects/objects/factory/containers/protos/WoodenBox.proto"

WorldInfo {
}
Viewpoint {
  orientation -0.3028928610508864 -0.11894819305547893 0.9455724414835939 3.8526965546943415
  position 1.4838924463598109 1.2598997286580924 1.482109243490566
  follow "my_robot"
}
TexturedBackground {
}
TexturedBackgroundLight {
}
CircleArena {
}
Robot {
  children [
    HingeJoint {
      jointParameters HingeJointParameters {
        axis 0 1 0
        anchor 0 0 0.025
      }
      device [
        RotationalMotor {
          name "left wheel motor"
        }
      ]
      endPoint Solid {
        translation 0 0.045 0.025
        children [
          DEF WHEEL Pose {
            rotation 1 0 0 1.5707996938995747
            children [
              Shape {
                appearance PBRAppearance {
                  baseColor 1 0 0
                  roughness 1
                  metalness 0
                }
                geometry Cylinder {
                  height 0.01
                  radius 0.025
                }
              }
            ]
          }
        ]
        name "left wheel"
        boundingObject USE WHEEL
        physics Physics {
        }
      }
    }
    HingeJoint {
      jointParameters HingeJointParameters {
        axis 0 1 0
        anchor 0 0 0.025
      }
      device [
        RotationalMotor {
          name "right wheel motor"
        }
      ]
      endPoint Solid {
        translation 0 -0.045 0.025
        children [
          USE WHEEL
        ]
        name "right wheel"
        boundingObject USE WHEEL
        physics Physics {
        }
      }
    }
    Pose {
      translation 0 0 0.0415
      children [
        Shape {
          appearance PBRAppearance {
            baseColor 0 0 1
            roughness 1
            metalness 0
          }
          geometry DEF BODY Cylinder {
            height 0.08
            radius 0.045
          }
        }
      ]
    }
    DistanceSensor {
      translation 0.042 0.02 0.063
      rotation 0 0 1 0.5236003061004253
      children [
        DEF SENSOR Pose {
          rotation 0 1 0 1.5708
          children [
            Shape {
              appearance PBRAppearance {
                baseColor 1 1 0
                roughness 1
                metalness 0
              }
              geometry Cylinder {
                height 0.004
                radius 0.008
              }
            }
          ]
        }
      ]
      name "ds0"
      lookupTable [
        0 1020 0
        0.05 1020 0
        0.15 0 0
      ]
      numberOfRays 2
      aperture 1
    }
    DistanceSensor {
      translation 0.042 -0.02 0.063
      rotation 0 0 1 -0.5235996938995747
      children [
        USE SENSOR
      ]
      name "ds1"
      lookupTable [
        0 1020 0
        0.05 1020 0
        0.15 0 0
      ]
      numberOfRays 2
      aperture 1
    }
  ]
  name "my_robot"
  boundingObject Pose {
    translation 0 0 0.0415
    children [
      USE BODY
    ]
  }
  physics Physics {
  }
  controller "<extern>"
}
WoodenBox {
  translation 0.51 0 0.1
  size 0.2 0.2 0.2
}
WoodenBox {
  translation -0.2 -0.42 0.06
  name "wooden box(2)"
  size 0.1 0.1 0.1
}
WoodenBox {
  translation 0.01 0.53 0.03
  name "wooden box(1)"
  size 0.05 0.05 0.05
}
